<!DOCTYPE html>
<head><title>Manejo de errores para Callbacks-Promesas-Async</title>
</head>
<body>
    <script>
        // 3 MANERAS DE MANEJO DE ERRORES EN OPERACIONES ASÍNCRONAS (Callbacks, Promesas, Async-Await)
        
        //Función ejemplo:
        function sumarNumeros(a, b){
            setTimeout(function(){
                console.log(a + b);
            }, 2000); // con demora para que se ejecute la función de 2 segundos
        }

        sumarNumeros(1, 2);

        //CALLBACKS
        function sumarNumeros1(a, b, callback){
            setTimeout(function(){
                if(typeof a != 'number' || typeof b != 'number'){
                    return callback(new Error('Algún argumento no es número'));
                }
                callback(null, a+b);
            }, 2000); // con demora para que se ejecute la función de 2 segundos
        }

        sumarNumeros1("1", 2, function(error, resultado){ //detro de la función "sumarNumeros" pasamos un parámetro mal, es dicir que no sea de tipo número para que a propósito nos muestre el mensaje de "error" en consola
            if(error){
               console.error(error);
            }else {
                console.log('resultado');
            }  
        });

        //PROMESAS
        function sumarNumeros2(a, b){
            return new Promise(function(resolve, reject){
                setTimeout(function(){
                    if(typeof a != 'number' || typeof b != 'number'){
                        reject(new Error("Ambos argumentos deben ser números"));
                    }else {
                        resolve(a + b);
                    }
                }, 2000); 
            })
        }

        sumarNumeros2("$", 2) //detro de la función "sumarNumeros" pasamos un parámetro mal, es dicir que no sea de tipo número para que a propósito nos muestre el mensaje de "error" en consola
        .then(function(resultado){
            console.log(resultado);
        }).catch(function(error){
            console.error(error);
        })

        // ASYNC-AWAIT 
        async function sumarNumeros3(a, b){
            if(typeof a != 'number' || typeof b != 'number'){
                throw new Error('Alguno de los argumentos no es número')
            }
            return a + b
        }

        async function manejarErrores(){
            try{
                let resultado= await sumarNumeros3(2, ); //detro de la función "sumarNumeros" pasamos un parámetro mal, es dicir que no sea de tipo número para que a propósito nos muestre el mensaje de "error" en consola
                console.log(resultado);
            } catch(error){
                console.error(error.message);
            }
        }

        manejarErrores();

    </script>
</body>
</html>